Problem installing fixture 'collection_record.auth.user.json.bz2': Traceback (most recent call last):
  File "/home/mredar/Documents/workspace/pyVirtualEnvs/RecordExpressVEnv/local/lib/python2.7/site-packages/django/core/management/commands/loaddata.py", line 226, in handle
    connection.check_constraints(table_names=table_names)
  File "/home/mredar/Documents/workspace/pyVirtualEnvs/RecordExpressVEnv/local/lib/python2.7/site-packages/django/db/backends/sqlite3/base.py", line 323, in check_constraints
    referenced_table_name, referenced_column_name))
IntegrityError: The row in table 'collection_record_collectionrecord' with primary key 'ark:/13030/c8s180ts' has an invalid foreign key: collection_record_collectionrecord.publisher_id contains a value '1' that does not have a corresponding value in collection_record_publishinginstitution.id.

testDeletionOfDCTerm (collection_record.tests.tests.CollectionRecordEditTestCase)
Test the deletion of a term ... ERROR
Problem installing fixture 'collection_record.auth.user.json.bz2': Traceback (most recent call last):
  File "/home/mredar/Documents/workspace/pyVirtualEnvs/RecordExpressVEnv/local/lib/python2.7/site-packages/django/core/management/commands/loaddata.py", line 226, in handle
    connection.check_constraints(table_names=table_names)
  File "/home/mredar/Documents/workspace/pyVirtualEnvs/RecordExpressVEnv/local/lib/python2.7/site-packages/django/db/backends/sqlite3/base.py", line 323, in check_constraints
    referenced_table_name, referenced_column_name))
IntegrityError: The row in table 'collection_record_collectionrecord' with primary key 'ark:/13030/c8s180ts' has an invalid foreign key: collection_record_collectionrecord.publisher_id contains a value '1' that does not have a corresponding value in collection_record_publishinginstitution.id.

testEditAttr (collection_record.tests.tests.CollectionRecordEditTestCase)
Edit a directly associated value of the Record ... ERROR
Problem installing fixture 'collection_record.auth.user.json.bz2': Traceback (most recent call last):
  File "/home/mredar/Documents/workspace/pyVirtualEnvs/RecordExpressVEnv/local/lib/python2.7/site-packages/django/core/management/commands/loaddata.py", line 226, in handle
    connection.check_constraints(table_names=table_names)
  File "/home/mredar/Documents/workspace/pyVirtualEnvs/RecordExpressVEnv/local/lib/python2.7/site-packages/django/db/backends/sqlite3/base.py", line 323, in check_constraints
    referenced_table_name, referenced_column_name))
IntegrityError: The row in table 'collection_record_collectionrecord' with primary key 'ark:/13030/c8s180ts' has an invalid foreign key: collection_record_collectionrecord.publisher_id contains a value '1' that does not have a corresponding value in collection_record_publishinginstitution.id.

testEditDCTerm (collection_record.tests.tests.CollectionRecordEditTestCase)
Test the editing of a term stored in an associated DC object ... ERROR
Problem installing fixture 'collection_record.auth.user.json.bz2': Traceback (most recent call last):
  File "/home/mredar/Documents/workspace/pyVirtualEnvs/RecordExpressVEnv/local/lib/python2.7/site-packages/django/core/management/commands/loaddata.py", line 226, in handle
    connection.check_constraints(table_names=table_names)
  File "/home/mredar/Documents/workspace/pyVirtualEnvs/RecordExpressVEnv/local/lib/python2.7/site-packages/django/db/backends/sqlite3/base.py", line 323, in check_constraints
    referenced_table_name, referenced_column_name))
IntegrityError: The row in table 'collection_record_collectionrecord' with primary key 'ark:/13030/c8s180ts' has an invalid foreign key: collection_record_collectionrecord.publisher_id contains a value '1' that does not have a corresponding value in collection_record_publishinginstitution.id.

testEditPageAuth (collection_record.tests.tests.CollectionRecordEditTestCase) ... ERROR
testNewForm (collection_record.tests.tests.CollectionRecordFormTestCase) ... ok
testEAD_file_remove_on_delete (collection_record.tests.tests.CollectionRecordModelTest)
Test that the EAD xml file is removed when the Collection Record is ... ERROR
testEAD_file_save (collection_record.tests.tests.CollectionRecordModelTest) ... FAIL
testEAD_iso_date (collection_record.tests.tests.CollectionRecordModelTest)
Check that the unitdate "normal" attribute only shows up for ... ERROR
testEAD_xml_output (collection_record.tests.tests.CollectionRecordModelTest)
Test the ead string output for a CollectionRecord. Check unicode ... ERROR
testEAD_xml_with_files_output (collection_record.tests.tests.CollectionRecordModelTest) ... ERROR
testEZID_DublinCoreUpdate (collection_record.tests.tests.CollectionRecordModelTest)
Test that the Dublin Core attrs of the EZID get updateed by ... ok
testModelExists (collection_record.tests.tests.CollectionRecordModelTest) ... ok
testXMLURL (collection_record.tests.tests.CollectionRecordModelTest)
test that the xml url function exists & returns something. ... ok
Problem installing fixture 'collection_record.auth.user.json.bz2': Traceback (most recent call last):
  File "/home/mredar/Documents/workspace/pyVirtualEnvs/RecordExpressVEnv/local/lib/python2.7/site-packages/django/core/management/commands/loaddata.py", line 226, in handle
    connection.check_constraints(table_names=table_names)
  File "/home/mredar/Documents/workspace/pyVirtualEnvs/RecordExpressVEnv/local/lib/python2.7/site-packages/django/db/backends/sqlite3/base.py", line 323, in check_constraints
    referenced_table_name, referenced_column_name))
IntegrityError: The row in table 'collection_record_collectionrecord' with primary key 'ark:/13030/c8s180ts' has an invalid foreign key: collection_record_collectionrecord.publisher_id contains a value '1' that does not have a corresponding value in collection_record_publishinginstitution.id.

testNoObject (collection_record.tests.tests.CollectionRecordPermissionsBackendTestCase) ... ERROR
Problem installing fixture 'collection_record.auth.user.json.bz2': Traceback (most recent call last):
  File "/home/mredar/Documents/workspace/pyVirtualEnvs/RecordExpressVEnv/local/lib/python2.7/site-packages/django/core/management/commands/loaddata.py", line 226, in handle
    connection.check_constraints(table_names=table_names)
  File "/home/mredar/Documents/workspace/pyVirtualEnvs/RecordExpressVEnv/local/lib/python2.7/site-packages/django/db/backends/sqlite3/base.py", line 323, in check_constraints
    referenced_table_name, referenced_column_name))
IntegrityError: The row in table 'collection_record_collectionrecord' with primary key 'ark:/13030/c8s180ts' has an invalid foreign key: collection_record_collectionrecord.publisher_id contains a value '1' that does not have a corresponding value in collection_record_publishinginstitution.id.

testUserNotAuthenticated (collection_record.tests.tests.CollectionRecordPermissionsBackendTestCase)
Test when the user object has not been authenticated ... ERROR
testLinksOnCollectionRecordListPage (collection_record.tests.tests.CollectionRecordViewAllTestCase)
Check that some links do exist on the collection record list page ... ERROR
testViewAllCollectionRecords (collection_record.tests.tests.CollectionRecordViewAllTestCase)
Verify that the user can see their institution's collection records ... ERROR
testDuplicateLocalID (collection_record.tests.tests.NewCollectionRecordViewTestCase)
Test that duplicate local IDs can be entered. Some insts use a ... ERROR
testNewView (collection_record.tests.tests.NewCollectionRecordViewTestCase)
Test the view for creating new collection records. ... ERROR
testNewWithARK (collection_record.tests.tests.NewCollectionRecordViewTestCase)
Test the collection editor basic function when you've got an ARK already ... ERROR
testNewWithDCView (collection_record.tests.tests.NewCollectionRecordViewTestCase) ... ERROR
Problem installing fixture 'collection_record.auth.user.json.bz2': Traceback (most recent call last):
  File "/home/mredar/Documents/workspace/pyVirtualEnvs/RecordExpressVEnv/local/lib/python2.7/site-packages/django/core/management/commands/loaddata.py", line 226, in handle
    connection.check_constraints(table_names=table_names)
  File "/home/mredar/Documents/workspace/pyVirtualEnvs/RecordExpressVEnv/local/lib/python2.7/site-packages/django/db/backends/sqlite3/base.py", line 323, in check_constraints
    referenced_table_name, referenced_column_name))
IntegrityError: The row in table 'collection_record_collectionrecord' with primary key 'ark:/13030/c8s180ts' has an invalid foreign key: collection_record_collectionrecord.publisher_id contains a value '1' that does not have a corresponding value in collection_record_publishinginstitution.id.

testFileHandle (collection_record.tests.tests.SupplementalFileTestCase) ... ok
Problem installing fixture 'collection_record.auth.user.json.bz2': Traceback (most recent call last):
  File "/home/mredar/Documents/workspace/pyVirtualEnvs/RecordExpressVEnv/local/lib/python2.7/site-packages/django/core/management/commands/loaddata.py", line 226, in handle
    connection.check_constraints(table_names=table_names)
  File "/home/mredar/Documents/workspace/pyVirtualEnvs/RecordExpressVEnv/local/lib/python2.7/site-packages/django/db/backends/sqlite3/base.py", line 323, in check_constraints
    referenced_table_name, referenced_column_name))
IntegrityError: The row in table 'collection_record_collectionrecord' with primary key 'ark:/13030/c8s180ts' has an invalid foreign key: collection_record_collectionrecord.publisher_id contains a value '1' that does not have a corresponding value in collection_record_publishinginstitution.id.

testRipToText (collection_record.tests.tests.SupplementalFileTestCase) ... ERROR
Problem installing fixture 'collection_record.auth.user.json.bz2': Traceback (most recent call last):
  File "/home/mredar/Documents/workspace/pyVirtualEnvs/RecordExpressVEnv/local/lib/python2.7/site-packages/django/core/management/commands/loaddata.py", line 226, in handle
    connection.check_constraints(table_names=table_names)
  File "/home/mredar/Documents/workspace/pyVirtualEnvs/RecordExpressVEnv/local/lib/python2.7/site-packages/django/db/backends/sqlite3/base.py", line 323, in check_constraints
    referenced_table_name, referenced_column_name))
IntegrityError: The row in table 'collection_record_collectionrecord' with primary key 'ark:/13030/c8s180ts' has an invalid foreign key: collection_record_collectionrecord.publisher_id contains a value '1' that does not have a corresponding value in collection_record_publishinginstitution.id.

testTextFilePath (collection_record.tests.tests.SupplementalFileTestCase)
Check that the name of the txt file is correct ... ok
Problem installing fixture 'collection_record.auth.user.json.bz2': Traceback (most recent call last):
  File "/home/mredar/Documents/workspace/pyVirtualEnvs/RecordExpressVEnv/local/lib/python2.7/site-packages/django/core/management/commands/loaddata.py", line 226, in handle
    connection.check_constraints(table_names=table_names)
  File "/home/mredar/Documents/workspace/pyVirtualEnvs/RecordExpressVEnv/local/lib/python2.7/site-packages/django/db/backends/sqlite3/base.py", line 323, in check_constraints
    referenced_table_name, referenced_column_name))
IntegrityError: The row in table 'collection_record_collectionrecord' with primary key 'ark:/13030/c8s180ts' has an invalid foreign key: collection_record_collectionrecord.publisher_id contains a value '1' that does not have a corresponding value in collection_record_publishinginstitution.id.

testURL (collection_record.tests.tests.SupplementalFileTestCase)
Check that the url is correct for a file ... ok
Problem installing fixture 'collection_record.auth.user.json.bz2': Traceback (most recent call last):
  File "/home/mredar/Documents/workspace/pyVirtualEnvs/RecordExpressVEnv/local/lib/python2.7/site-packages/django/core/management/commands/loaddata.py", line 226, in handle
    connection.check_constraints(table_names=table_names)
  File "/home/mredar/Documents/workspace/pyVirtualEnvs/RecordExpressVEnv/local/lib/python2.7/site-packages/django/db/backends/sqlite3/base.py", line 323, in check_constraints
    referenced_table_name, referenced_column_name))
IntegrityError: The row in table 'collection_record_collectionrecord' with primary key 'ark:/13030/c8s180ts' has an invalid foreign key: collection_record_collectionrecord.publisher_id contains a value '1' that does not have a corresponding value in collection_record_publishinginstitution.id.

testOACView (collection_record.tests.tests.CollectionRecordOACViewTestCase) ... ERROR
Problem installing fixture 'collection_record.auth.user.json.bz2': Traceback (most recent call last):
  File "/home/mredar/Documents/workspace/pyVirtualEnvs/RecordExpressVEnv/local/lib/python2.7/site-packages/django/core/management/commands/loaddata.py", line 226, in handle
    connection.check_constraints(table_names=table_names)
  File "/home/mredar/Documents/workspace/pyVirtualEnvs/RecordExpressVEnv/local/lib/python2.7/site-packages/django/db/backends/sqlite3/base.py", line 323, in check_constraints
    referenced_table_name, referenced_column_name))
IntegrityError: The row in table 'collection_record_collectionrecord' with primary key 'ark:/13030/c8s180ts' has an invalid foreign key: collection_record_collectionrecord.publisher_id contains a value '1' that does not have a corresponding value in collection_record_publishinginstitution.id.

testOACViewNotOwner (collection_record.tests.tests.CollectionRecordOACViewTestCase)
Check that the "Edit" button link doesn't appear in the preview ... ERROR

======================================================================
ERROR: testDeletionOfDCTerm (collection_record.tests.tests.CollectionRecordEditTestCase)
Test the deletion of a term
----------------------------------------------------------------------
Traceback (most recent call last):
  File "/home/mredar/Documents/workspace/RecordExpress/collection_record/tests/tests.py", line 253, in setUp
    if not os.path.isdir(rec.ead_dir):
  File "/home/mredar/Documents/workspace/RecordExpress/collection_record/models.py", line 133, in ead_dir
    return  os.path.join(self.dir_root, self.publisher.cdlpath)
  File "/home/mredar/Documents/workspace/pyVirtualEnvs/RecordExpressVEnv/local/lib/python2.7/site-packages/django/db/models/fields/related.py", line 350, in __get__
    rel_obj = qs.get(**params)
  File "/home/mredar/Documents/workspace/pyVirtualEnvs/RecordExpressVEnv/local/lib/python2.7/site-packages/django/db/models/query.py", line 366, in get
    % self.model._meta.object_name)
DoesNotExist: PublishingInstitution matching query does not exist.

======================================================================
ERROR: testEditAttr (collection_record.tests.tests.CollectionRecordEditTestCase)
Edit a directly associated value of the Record
----------------------------------------------------------------------
Traceback (most recent call last):
  File "/home/mredar/Documents/workspace/RecordExpress/collection_record/tests/tests.py", line 253, in setUp
    if not os.path.isdir(rec.ead_dir):
  File "/home/mredar/Documents/workspace/RecordExpress/collection_record/models.py", line 133, in ead_dir
    return  os.path.join(self.dir_root, self.publisher.cdlpath)
  File "/home/mredar/Documents/workspace/pyVirtualEnvs/RecordExpressVEnv/local/lib/python2.7/site-packages/django/db/models/fields/related.py", line 350, in __get__
    rel_obj = qs.get(**params)
  File "/home/mredar/Documents/workspace/pyVirtualEnvs/RecordExpressVEnv/local/lib/python2.7/site-packages/django/db/models/query.py", line 366, in get
    % self.model._meta.object_name)
DoesNotExist: PublishingInstitution matching query does not exist.

======================================================================
ERROR: testEditDCTerm (collection_record.tests.tests.CollectionRecordEditTestCase)
Test the editing of a term stored in an associated DC object
----------------------------------------------------------------------
Traceback (most recent call last):
  File "/home/mredar/Documents/workspace/RecordExpress/collection_record/tests/tests.py", line 253, in setUp
    if not os.path.isdir(rec.ead_dir):
  File "/home/mredar/Documents/workspace/RecordExpress/collection_record/models.py", line 133, in ead_dir
    return  os.path.join(self.dir_root, self.publisher.cdlpath)
  File "/home/mredar/Documents/workspace/pyVirtualEnvs/RecordExpressVEnv/local/lib/python2.7/site-packages/django/db/models/fields/related.py", line 350, in __get__
    rel_obj = qs.get(**params)
  File "/home/mredar/Documents/workspace/pyVirtualEnvs/RecordExpressVEnv/local/lib/python2.7/site-packages/django/db/models/query.py", line 366, in get
    % self.model._meta.object_name)
DoesNotExist: PublishingInstitution matching query does not exist.

======================================================================
ERROR: testEditPageAuth (collection_record.tests.tests.CollectionRecordEditTestCase)
----------------------------------------------------------------------
Traceback (most recent call last):
  File "/home/mredar/Documents/workspace/RecordExpress/collection_record/tests/tests.py", line 253, in setUp
    if not os.path.isdir(rec.ead_dir):
  File "/home/mredar/Documents/workspace/RecordExpress/collection_record/models.py", line 133, in ead_dir
    return  os.path.join(self.dir_root, self.publisher.cdlpath)
  File "/home/mredar/Documents/workspace/pyVirtualEnvs/RecordExpressVEnv/local/lib/python2.7/site-packages/django/db/models/fields/related.py", line 350, in __get__
    rel_obj = qs.get(**params)
  File "/home/mredar/Documents/workspace/pyVirtualEnvs/RecordExpressVEnv/local/lib/python2.7/site-packages/django/db/models/query.py", line 366, in get
    % self.model._meta.object_name)
DoesNotExist: PublishingInstitution matching query does not exist.

======================================================================
ERROR: testEAD_file_remove_on_delete (collection_record.tests.tests.CollectionRecordModelTest)
Test that the EAD xml file is removed when the Collection Record is
----------------------------------------------------------------------
Traceback (most recent call last):
  File "/home/mredar/Documents/workspace/RecordExpress/collection_record/tests/tests.py", line 168, in testEAD_file_remove_on_delete
    rec.delete()
  File "/home/mredar/Documents/workspace/RecordExpress/collection_record/models.py", line 147, in delete
    with open(log_path, 'w') as logfile:
IOError: [Errno 2] No such file or directory: u'/home/mredar/log/holdMets/ark-13030-c8s180ts'

======================================================================
ERROR: testEAD_iso_date (collection_record.tests.tests.CollectionRecordModelTest)
Check that the unitdate "normal" attribute only shows up for
----------------------------------------------------------------------
Traceback (most recent call last):
  File "/home/mredar/Documents/workspace/RecordExpress/collection_record/tests/tests.py", line 102, in testEAD_iso_date
    ead_xml = rec.ead_xml
  File "/home/mredar/Documents/workspace/RecordExpress/collection_record/models.py", line 267, in ead_xml
    if self.publisher.parent_institution:
AttributeError: 'PublishingInstitution' object has no attribute 'parent_institution'

======================================================================
ERROR: testEAD_xml_output (collection_record.tests.tests.CollectionRecordModelTest)
Test the ead string output for a CollectionRecord. Check unicode
----------------------------------------------------------------------
Traceback (most recent call last):
  File "/home/mredar/Documents/workspace/RecordExpress/collection_record/tests/tests.py", line 60, in testEAD_xml_output
    ead_xml = rec.ead_xml
  File "/home/mredar/Documents/workspace/RecordExpress/collection_record/models.py", line 267, in ead_xml
    if self.publisher.parent_institution:
AttributeError: 'PublishingInstitution' object has no attribute 'parent_institution'

======================================================================
ERROR: testEAD_xml_with_files_output (collection_record.tests.tests.CollectionRecordModelTest)
----------------------------------------------------------------------
Traceback (most recent call last):
  File "/home/mredar/Documents/workspace/RecordExpress/collection_record/tests/tests.py", line 130, in testEAD_xml_with_files_output
    ead_xml = rec.ead_xml
  File "/home/mredar/Documents/workspace/RecordExpress/collection_record/models.py", line 267, in ead_xml
    if self.publisher.parent_institution:
AttributeError: 'PublishingInstitution' object has no attribute 'parent_institution'

======================================================================
ERROR: testNoObject (collection_record.tests.tests.CollectionRecordPermissionsBackendTestCase)
----------------------------------------------------------------------
Traceback (most recent call last):
  File "/home/mredar/Documents/workspace/RecordExpress/collection_record/tests/tests.py", line 613, in testNoObject
    u = User.objects.get(pk=1)
  File "/home/mredar/Documents/workspace/pyVirtualEnvs/RecordExpressVEnv/local/lib/python2.7/site-packages/django/db/models/manager.py", line 131, in get
    return self.get_query_set().get(*args, **kwargs)
  File "/home/mredar/Documents/workspace/pyVirtualEnvs/RecordExpressVEnv/local/lib/python2.7/site-packages/django/db/models/query.py", line 366, in get
    % self.model._meta.object_name)
DoesNotExist: User matching query does not exist.

======================================================================
ERROR: testUserNotAuthenticated (collection_record.tests.tests.CollectionRecordPermissionsBackendTestCase)
Test when the user object has not been authenticated
----------------------------------------------------------------------
Traceback (most recent call last):
  File "/home/mredar/Documents/workspace/RecordExpress/collection_record/tests/tests.py", line 609, in testUserNotAuthenticated
    u = User.objects.get(pk=1)
  File "/home/mredar/Documents/workspace/pyVirtualEnvs/RecordExpressVEnv/local/lib/python2.7/site-packages/django/db/models/manager.py", line 131, in get
    return self.get_query_set().get(*args, **kwargs)
  File "/home/mredar/Documents/workspace/pyVirtualEnvs/RecordExpressVEnv/local/lib/python2.7/site-packages/django/db/models/query.py", line 366, in get
    % self.model._meta.object_name)
DoesNotExist: User matching query does not exist.

======================================================================
ERROR: testLinksOnCollectionRecordListPage (collection_record.tests.tests.CollectionRecordViewAllTestCase)
Check that some links do exist on the collection record list page
----------------------------------------------------------------------
Traceback (most recent call last):
  File "/home/mredar/Documents/workspace/RecordExpress/collection_record/tests/tests.py", line 211, in testLinksOnCollectionRecordListPage
    url = reverse('collection_record_view_all', args=None)
  File "/home/mredar/Documents/workspace/pyVirtualEnvs/RecordExpressVEnv/local/lib/python2.7/site-packages/django/core/urlresolvers.py", line 476, in reverse
    return iri_to_uri(resolver._reverse_with_prefix(view, prefix, *args, **kwargs))
  File "/home/mredar/Documents/workspace/pyVirtualEnvs/RecordExpressVEnv/local/lib/python2.7/site-packages/django/core/urlresolvers.py", line 396, in _reverse_with_prefix
    "arguments '%s' not found." % (lookup_view_s, args, kwargs))
NoReverseMatch: Reverse for 'collection_record_view_all' with arguments '()' and keyword arguments '{}' not found.

======================================================================
ERROR: testViewAllCollectionRecords (collection_record.tests.tests.CollectionRecordViewAllTestCase)
Verify that the user can see their institution's collection records
----------------------------------------------------------------------
Traceback (most recent call last):
  File "/home/mredar/Documents/workspace/RecordExpress/collection_record/tests/tests.py", line 193, in testViewAllCollectionRecords
    url = reverse('collection_record_view_all', args=None)
  File "/home/mredar/Documents/workspace/pyVirtualEnvs/RecordExpressVEnv/local/lib/python2.7/site-packages/django/core/urlresolvers.py", line 476, in reverse
    return iri_to_uri(resolver._reverse_with_prefix(view, prefix, *args, **kwargs))
  File "/home/mredar/Documents/workspace/pyVirtualEnvs/RecordExpressVEnv/local/lib/python2.7/site-packages/django/core/urlresolvers.py", line 396, in _reverse_with_prefix
    "arguments '%s' not found." % (lookup_view_s, args, kwargs))
NoReverseMatch: Reverse for 'collection_record_view_all' with arguments '()' and keyword arguments '{}' not found.

======================================================================
ERROR: testDuplicateLocalID (collection_record.tests.tests.NewCollectionRecordViewTestCase)
Test that duplicate local IDs can be entered. Some insts use a
----------------------------------------------------------------------
Traceback (most recent call last):
  File "/home/mredar/Documents/workspace/RecordExpress/collection_record/tests/tests.py", line 344, in setUp
    testuser = User.objects.get(username='testuser')
  File "/home/mredar/Documents/workspace/pyVirtualEnvs/RecordExpressVEnv/local/lib/python2.7/site-packages/django/db/models/manager.py", line 131, in get
    return self.get_query_set().get(*args, **kwargs)
  File "/home/mredar/Documents/workspace/pyVirtualEnvs/RecordExpressVEnv/local/lib/python2.7/site-packages/django/db/models/query.py", line 366, in get
    % self.model._meta.object_name)
DoesNotExist: User matching query does not exist.

======================================================================
ERROR: testNewView (collection_record.tests.tests.NewCollectionRecordViewTestCase)
Test the view for creating new collection records.
----------------------------------------------------------------------
Traceback (most recent call last):
  File "/home/mredar/Documents/workspace/RecordExpress/collection_record/tests/tests.py", line 344, in setUp
    testuser = User.objects.get(username='testuser')
  File "/home/mredar/Documents/workspace/pyVirtualEnvs/RecordExpressVEnv/local/lib/python2.7/site-packages/django/db/models/manager.py", line 131, in get
    return self.get_query_set().get(*args, **kwargs)
  File "/home/mredar/Documents/workspace/pyVirtualEnvs/RecordExpressVEnv/local/lib/python2.7/site-packages/django/db/models/query.py", line 366, in get
    % self.model._meta.object_name)
DoesNotExist: User matching query does not exist.

======================================================================
ERROR: testNewWithARK (collection_record.tests.tests.NewCollectionRecordViewTestCase)
Test the collection editor basic function when you've got an ARK already
----------------------------------------------------------------------
Traceback (most recent call last):
  File "/home/mredar/Documents/workspace/RecordExpress/collection_record/tests/tests.py", line 344, in setUp
    testuser = User.objects.get(username='testuser')
  File "/home/mredar/Documents/workspace/pyVirtualEnvs/RecordExpressVEnv/local/lib/python2.7/site-packages/django/db/models/manager.py", line 131, in get
    return self.get_query_set().get(*args, **kwargs)
  File "/home/mredar/Documents/workspace/pyVirtualEnvs/RecordExpressVEnv/local/lib/python2.7/site-packages/django/db/models/query.py", line 366, in get
    % self.model._meta.object_name)
DoesNotExist: User matching query does not exist.

======================================================================
ERROR: testNewWithDCView (collection_record.tests.tests.NewCollectionRecordViewTestCase)
----------------------------------------------------------------------
Traceback (most recent call last):
  File "/home/mredar/Documents/workspace/RecordExpress/collection_record/tests/tests.py", line 344, in setUp
    testuser = User.objects.get(username='testuser')
  File "/home/mredar/Documents/workspace/pyVirtualEnvs/RecordExpressVEnv/local/lib/python2.7/site-packages/django/db/models/manager.py", line 131, in get
    return self.get_query_set().get(*args, **kwargs)
  File "/home/mredar/Documents/workspace/pyVirtualEnvs/RecordExpressVEnv/local/lib/python2.7/site-packages/django/db/models/query.py", line 366, in get
    % self.model._meta.object_name)
DoesNotExist: User matching query does not exist.

======================================================================
ERROR: testRipToText (collection_record.tests.tests.SupplementalFileTestCase)
----------------------------------------------------------------------
Traceback (most recent call last):
  File "/home/mredar/Documents/workspace/RecordExpress/collection_record/tests/tests.py", line 648, in testRipToText
    sf.rip_to_text()
  File "/home/mredar/Documents/workspace/RecordExpress/collection_record/models.py", line 333, in rip_to_text
    p = subprocess.Popen(args, stdout=subprocess.PIPE, stderr=subprocess.PIPE )
  File "/usr/lib/python2.7/subprocess.py", line 679, in __init__
    errread, errwrite)
  File "/usr/lib/python2.7/subprocess.py", line 1259, in _execute_child
    raise child_exception
OSError: [Errno 2] No such file or directory

======================================================================
ERROR: testOACView (collection_record.tests.tests.CollectionRecordOACViewTestCase)
----------------------------------------------------------------------
Traceback (most recent call last):
  File "/home/mredar/Documents/workspace/RecordExpress/collection_record/tests/tests.py", line 560, in testOACView
    rec = CollectionRecord.objects.get(pk="ark:/13030/c8s180ts")
  File "/home/mredar/Documents/workspace/pyVirtualEnvs/RecordExpressVEnv/local/lib/python2.7/site-packages/django/db/models/manager.py", line 131, in get
    return self.get_query_set().get(*args, **kwargs)
  File "/home/mredar/Documents/workspace/pyVirtualEnvs/RecordExpressVEnv/local/lib/python2.7/site-packages/django/db/models/query.py", line 366, in get
    % self.model._meta.object_name)
DoesNotExist: CollectionRecord matching query does not exist.

======================================================================
ERROR: testOACViewNotOwner (collection_record.tests.tests.CollectionRecordOACViewTestCase)
Check that the "Edit" button link doesn't appear in the preview
----------------------------------------------------------------------
Traceback (most recent call last):
  File "/home/mredar/Documents/workspace/RecordExpress/collection_record/tests/tests.py", line 580, in testOACViewNotOwner
    rec = CollectionRecord.objects.get(pk="ark:/13030/c8s180ts")
  File "/home/mredar/Documents/workspace/pyVirtualEnvs/RecordExpressVEnv/local/lib/python2.7/site-packages/django/db/models/manager.py", line 131, in get
    return self.get_query_set().get(*args, **kwargs)
  File "/home/mredar/Documents/workspace/pyVirtualEnvs/RecordExpressVEnv/local/lib/python2.7/site-packages/django/db/models/query.py", line 366, in get
    % self.model._meta.object_name)
DoesNotExist: CollectionRecord matching query does not exist.

======================================================================
FAIL: testEAD_file_save (collection_record.tests.tests.CollectionRecordModelTest)
----------------------------------------------------------------------
Traceback (most recent call last):
  File "/home/mredar/Documents/workspace/RecordExpress/collection_record/tests/tests.py", line 148, in testEAD_file_save
    self.fail('Did not create EAD file %s' %(rec.ead_filename,))
AssertionError: Did not create EAD file /home/mredar/Documents/workspace/RecordExpress/collection_record/tests/data/cdl/c8s180ts.xml

----------------------------------------------------------------------
Ran 27 tests in 1.485s

FAILED (failures=1, errors=19)
Creating test database for alias 'default' (':memory:')...
Creating tables ...
Creating table auth_permission
Creating table auth_group_permissions
Creating table auth_group
Creating table auth_user_user_permissions
Creating table auth_user_groups
Creating table auth_user
Creating table django_content_type
Creating table django_session
Creating table django_site
Creating table django_admin_log
Creating table dublincore_qualifieddublincoreelement
Creating table dublincore_qualifieddublincoreelementhistory
Creating table collection_record_publishinginstitution
Creating table collection_record_collectionrecord
Creating table collection_record_supplementalfile
Installing custom SQL ...
Installing indexes ...
Installed 0 object(s) from 0 fixture(s)
Destroying test database for alias 'default' (':memory:')...
